Workbook

Sheet Instructions
A1: INSTRUCTIONS
A3: Why we use Excel
A14: Exporting from ARGUS to Excel
A15: 1 | B15: Select "PROPERTY REPORTS" > "CASH FLOW" from reports tab
A20: 2 | B20: Select "REPORT" > "REPORT OPTIONS"
A29: 3 | B29: Scroll down midway and select "YES" for "PRINT OCCUPANCY SUMMARY"
A58: 4 | B58: Select "EXPORT" > "MICROSOFT EXCEL"

Sheet Property Summary
A2: PROPERTY INFORMATION | F2: REVERSION CALCULATION | K2: RETURN SUMMARY
A3: Property | B3: The Empire State Building | C3: Address | D3: 350 Fifth Avenue | F3: Sale Year | G3: =D6 -> 10 | I3: =INDEX(Proforma!$E$4:$P$4,MATCH(G3,Proforma!$E$3:$P$3,0)) -> 48944 | K3: Deal Unleveraged Profit | L3: =M3/$B$4 -> 688.226 | M3: =SUMIF($B$33:$M$33,">0",$B$33:$M$33)+SUMIF($B$33:$M$33,"<0",$B$33:$M$33) -> 1.9329288e+09
A4: RBA | B4: 2808567 | C4: City, State | D4: New York, NY | H4: PSF | I4: $ | K4: Deal Unleveraged IRR | M4: =XIRR(B33:M33,B18:M18) -> 0.08357549
A5: Purchase Price | B5: ='Observatory Analysis'!B5+'Building Analysis'!B5 -> 2.1392098e+09 | F5: Gross Sales Price | H5: =I5/$B$4 -> 892.57906 | I5: =SUM('Observatory Analysis'!$D$5+'Building Analysis'!$I$9) -> 2.5068681e+09 | K5: Deal Unleveraged Multiple | M5: =SUMIF(B33:M33,">"&0,B33:M33)/-SUMIF(B33:M33,"<"&0,B33:M33) -> 1.9035714
A6: Purchase Price (PSF) | B6: =B5/B4 -> 761.67307 | C6: Hold Period | D6: 10 | F6: Selling Expense | G6: 0.02 | H6: =I6/$B$4 -> -17.851581 | I6: =-I5*G6 -> -50137362 | K6: Deal Leveraged Profit | L6: =M6/$B$4 -> 429.13215 | M6: =SUMIF($B$41:$M$41,">0",$B$41:$M$41)+SUMIF($B$41:$M$41,"<0",$B$41:$M$41) -> 1.2052464e+09
A7: Going-In Cap Rate | B7: =B9/B5 -> 0.083974999 | C7: Analysis Start Date | D7: 45292 | F7: Net Sales Price | H7: =I7/$B$4 -> 874.72748 | I7: =SUM(I5:I6) -> 2.4567307e+09 | K7: Deal Leveraged IRR | M7: =XIRR(B41:M41,B18:M18) -> 0.095341793
A8: In Place Occupancy | B8: =C19 -> 0.88421604 | C8: Analysis End Date | D8: =EOMONTH(D7-1,D6*12) -> 48944 | F8: ="PV of Net Sales Price @ "&TEXT(M4,"0.00%")&" Discount Rate" -> PV of Net Sales Price @ 8.36% Discount Rate | H8: =I8/$B$4 -> 391.99546 | I8: =I7/(1+M4)^G3 -> 1.1009455e+09 | K8: Deal Leveraged Multiple | M8: =SUMIF(B41:M41,">"&0,B41:M41)/-SUMIF(B41:M41,"<"&0,B41:M41) -> 2.1268146
A9: YR1 NOI | B9: =C22 -> 179640144 | C9: ="Exit Forward NOI - YR"&D6&"" -> Exit Forward NOI - YR10 | D9: =INDEX($B$22:$M$22,MATCH($D$6+1,$B$17:$M$17,0)) -> 1.981071e+08 | F9: Less: Loan Balance | H9: =I9/$B$4 -> -347.12265 | I9: =SUM(B37:M37) -> -9.7491723e+08 | K9: ='Property Summary'!$A$60&" Profit" -> Capital Partner Profit | L9: =M9/$B$4 -> 407.67554 | M9: ='Waterfall Model'!R4 -> 1.1449841e+09
F10: Proceeds from Sale | H10: =I10/$B$4 -> 527.60482 | I10: =I7+I9 -> 1.4818135e+09 | K10: ='Property Summary'!$A$60&" IRR" -> Capital Partner IRR | M10: ='Waterfall Model'!P4 -> 0.095341793
A11: DEBT | F11: ="PV of Net Sales Price @ "&TEXT(M4,"0.00%")&" Discount Rate" -> PV of Net Sales Price @ 8.36% Discount Rate | H11: =I11/$B$4 -> 236.43786 | I11: =I10/(1+M4)^G3 -> 6.6405158e+08 | K11: ='Property Summary'!$A$60&" Multiple" -> Capital Partner Multiple | M11: ='Waterfall Model'!Q4 -> 2.1268146
A12: LTC | B12: 0.5 | C12: Loan Proceeds | D12: =B12*B5 -> 1.0696049e+09 | K12: ='Property Summary'!$A$59&" Profit" -> Sponsor Profit | L12: =M12/$B$4 -> 21.456608 | M12: ='Waterfall Model'!N4 -> 60262320
A13: 10YR UST | B13: 0.035 | C13: Term of Loan (Years) | D13: 10 | K13: ='Property Summary'!$A$59&" IRR" -> Sponsor IRR | M13: ='Waterfall Model'!L4 -> 0.095341793
A14: Spread | B14: 0.035 | C14: Interest Only (Years) | D14: 3 | K14: ='Property Summary'!$A$59&" Multiple" -> Sponsor Multiple | M14: ='Waterfall Model'!M4 -> 2.1268146
A15: Rate (Annual) | B15: =SUM(B13:B14) -> 0.07 | C15: Amortization (Years) | D15: 30
A17: CASH FLOW SUMMARY | B17: =Proforma!E3 -> 0 | C17: =Proforma!F3 -> 1 | D17: =Proforma!G3 -> 2 | E17: =Proforma!H3 -> 3 | F17: =Proforma!I3 -> 4 | G17: =Proforma!J3 -> 5 | H17: =Proforma!K3 -> 6 | I17: =Proforma!L3 -> 7 | ... M17: =Proforma!P3 -> 11
A18: Year Ending | B18: =Proforma!E4 -> 45292 | C18: =Proforma!F4 -> 45657 | D18: =Proforma!G4 -> 46022 | E18: =Proforma!H4 -> 46387 | F18: =Proforma!I4 -> 46752 | G18: =Proforma!J4 -> 47118 | H18: =Proforma!K4 -> 47483 | I18: =Proforma!L4 -> 47848 | ... M18: =Proforma!P4 -> 49309
A19: Average Occupancy | B19: - | C19: =Proforma!F6 -> 0.88421604 | D19: =Proforma!G6 -> 0.91714992 | E19: =Proforma!H6 -> 0.97081074 | F19: =Proforma!I6 -> 0.97584097 | G19: =Proforma!J6 -> 0.96203111 | H19: =Proforma!K6 -> 0.90869332 | I19: =Proforma!L6 -> 0.99193005 | J19: =Proforma!M6 -> 0.99292729 | ... M19: =Proforma!P6 -> 0.96345829
A20: Building NOI | B20: =Proforma!E37 -> 0 | C20: =Proforma!F37 -> 87248544 | D20: =Proforma!G37 -> 91652523 | E20: =Proforma!H37 -> 95756622 | F20: =Proforma!I37 -> 98326799 | G20: =Proforma!J37 -> 96446550 | H20: =Proforma!K37 -> 71090813 | I20: =Proforma!L37 -> 80711654 | ... M20: =Proforma!P37 -> 85482252
A21: Observatory NOI | B21: ='Observatory Analysis'!B13 -> 0 | C21: ='Observatory Analysis'!C13 -> 92391600 | D21: ='Observatory Analysis'!D13 -> 94239432 | E21: ='Observatory Analysis'!E13 -> 96124221 | F21: ='Observatory Analysis'!F13 -> 98046705 | G21: ='Observatory Analysis'!G13 -> 1.0000764e+08 | H21: ='Observatory Analysis'!H13 -> 1.0200779e+08 | I21: ='Observatory Analysis'!I13 -> 1.0404795e+08 | ... M21: ='Observatory Analysis'!M13 -> 1.1262484e+08
A22: PROPERTY LEVEL NOI | B22: 0 | C22: =C20+C21 -> 179640144 | D22: =D20+D21 -> 185891955 | E22: =E20+E21 -> 1.9188084e+08 | F22: =F20+F21 -> 1.963735e+08 | G22: =G20+G21 -> 1.9645419e+08 | H22: =H20+H21 -> 1.730986e+08 | I22: =I20+I21 -> 1.847596e+08 | J22: =J20+J21 -> 1.8835507e+08 | ... M22: =M20+M21 -> 1.981071e+08
A23: NOI Growth | B23: - | C23: 0 | D23: =(D22-C22)/C22 -> 0.034801859 | E23: =(E22-D22)/D22 -> 0.032217035 | F23: =(F22-E22)/E22 -> 0.023413809 | G23: =(G22-F22)/F22 -> 0.0004108757 | H23: =(H22-G22)/G22 -> -0.11888565 | I23: =(I22-H22)/H22 -> 0.067366209 | J23: =(J22-I22)/I22 -> 0.019460266 | K23: =(K22-J22)/J22 -> 0.015309257 | ... M23: =(M22-L22)/L22 -> 0.011380824
A25: Leasing Costs | B25: =-Proforma!E42 -> 0 | C25: =-Proforma!F42 -> -52346631 | D25: =-Proforma!G42 -> -34717449 | E25: =-Proforma!H42 -> -21201215 | F25: =-Proforma!I42 -> -15202057 | G25: =-Proforma!J42 -> -12932417 | H25: =-Proforma!K42 -> -75397937 | I25: =-Proforma!L42 -> -4731266 | ... M25: =-Proforma!P42 -> -18345095
A26: Building Capital Expenditures | B26: =-Proforma!E43 -> 0 | C26: =-Proforma!F43 -> -10608333 | D26: =-Proforma!G43 -> -10608833 | E26: =-Proforma!H43 -> -10609343 | F26: =-Proforma!I43 -> -4976530 | G26: =-Proforma!J43 -> -2227061 | H26: =-Proforma!K43 -> -27602 | I26: =-Proforma!L43 -> -28154 | ... M26: =-Proforma!P43 -> -30475
A27: Total Capital Improvements | B27: =SUM(B25:B26) -> 0 | C27: =SUM(C25:C26) -> -62954964 | D27: =SUM(D25:D26) -> -45326282 | E27: =SUM(E25:E26) -> -31810558 | F27: =SUM(F25:F26) -> -20178587 | G27: =SUM(G25:G26) -> -15159478 | H27: =SUM(H25:H26) -> -75425539 | I27: =SUM(I25:I26) -> -4759420 | ... M27: =SUM(M25:M26) -> -18375570
A29: Cash Flow Before Debt Service | C29: =C22+C27 -> 116685180 | D29: =D22+D27 -> 140565673 | E29: =E22+E27 -> 1.6007028e+08 | F29: =F22+F27 -> 1.7619492e+08 | G29: =G22+G27 -> 1.8129471e+08 | H29: =H22+H27 -> 97673066 | I29: =I22+I27 -> 1.8000018e+08 | J29: =J22+J27 -> 1.8308825e+08 | ... M29: =M22+M27 -> 1.7973153e+08
A31: ="Building Net Reversion " -> Building Net Reversion | C31: =IF(C17=$D$6,$I$7,0) -> 0 | D31: =IF(D17=$D$6,$I$7,0) -> 0 | E31: =IF(E17=$D$6,$I$7,0) -> 0 | F31: =IF(F17=$D$6,$I$7,0) -> 0 | G31: =IF(G17=$D$6,$I$7,0) -> 0 | H31: =IF(H17=$D$6,$I$7,0) -> 0 | I31: =IF(I17=$D$6,$I$7,0) -> 0 | J31: =IF(J17=$D$6,$I$7,0) -> 0 | ... M31: =IF(M17=$D$6,$I$7,0) -> 0
A33: Unleveraged Cash Flow | B33: =-B5*(B17<=$G$3) -> -2.1392098e+09 | C33: =SUM(C29,C31)*(C17<=$G$3) -> 116685180 | D33: =SUM(D29,D31)*(D17<=$G$3) -> 140565673 | E33: =SUM(E29,E31)*(E17<=$G$3) -> 1.6007028e+08 | F33: =SUM(F29,F31)*(F17<=$G$3) -> 1.7619492e+08 | G33: =SUM(G29,G31)*(G17<=$G$3) -> 1.8129471e+08 | H33: =SUM(H29,H31)*(H17<=$G$3) -> 97673066 | I33: =SUM(I29,I31)*(I17<=$G$3) -> 1.8000018e+08 | J33: =SUM(J29,J31)*(J17<=$G$3) -> 1.8308825e+08 | ... M33: =SUM(M29,M31)*(M17<=$G$3) -> 0
A35: Loan Proceeds | B35: =D12 -> 1.0696049e+09 | C35: 0 | D35: 0 | E35: 0 | F35: 0 | G35: 0 | H35: 0 | I35: 0 | J35: 0 | K35: 0 | L35: 0 | M35: 0
A36: Debt Service | B36: =SUM(Proforma!E53:E54) -> 0 | C36: =SUM(Proforma!F53:F54) -> -74872345 | D36: =SUM(Proforma!G53:G54) -> -74872345 | E36: =SUM(Proforma!H53:H54) -> -74872345 | F36: =SUM(Proforma!I53:I54) -> -85393299 | G36: =SUM(Proforma!J53:J54) -> -85393299 | H36: =SUM(Proforma!K53:K54) -> -85393299 | I36: =SUM(Proforma!L53:L54) -> -85393299 | ... M36: =SUM(Proforma!P53:P54) -> 0
A37: Principal Payoff | B37: =Proforma!E55 -> 0 | C37: =Proforma!F55 -> 0 | D37: =Proforma!G55 -> 0 | E37: =Proforma!H55 -> 0 | F37: =Proforma!I55 -> 0 | G37: =Proforma!J55 -> 0 | H37: =Proforma!K55 -> 0 | I37: =Proforma!L55 -> 0 | ... M37: =Proforma!P55 -> 0
A38: Total Financing | B38: =SUM(B35:B37) -> 1.0696049e+09 | C38: =SUM(C35:C37) -> -74872345 | D38: =SUM(D35:D37) -> -74872345 | E38: =SUM(E35:E37) -> -74872345 | F38: =SUM(F35:F37) -> -85393299 | G38: =SUM(G35:G37) -> -85393299 | H38: =SUM(H35:H37) -> -85393299 | I38: =SUM(I35:I37) -> -85393299 | ... M38: =SUM(M35:M37) -> 0
A39: DSCR | B39: - | C39: =IFERROR(-C22/C36,"") -> 2.3992857 | D39: =IFERROR(-D22/D36,"") -> 2.4827853 | E39: =IFERROR(-E22/E36,"") -> 2.5627733 | F39: =IFERROR(-F22/F36,"") -> 2.299636 | G39: =IFERROR(-G22/G36,"") -> 2.3005809 | H39: =IFERROR(-H22/H36,"") -> 2.0270748 | I39: =IFERROR(-I22/I36,"") -> 2.1636312 | J39: =IFERROR(-J22/J36,"") -> 2.205736 | ... M39: =IFERROR(-M22/M36,"")
A40: Debt Yield | B40: - | C40: =C22/$B$35 -> 0.16795 | D40: =D22/$B$35 -> 0.17379497 | E40: =E22/$B$35 -> 0.17939413 | F40: =F22/$B$35 -> 0.18359443 | G40: =G22/$B$35 -> 0.18366986 | H40: =H22/$B$35 -> 0.16183415 | I40: =I22/$B$35 -> 0.1727363 | J40: =J22/$B$35 -> 0.1760978 | ... M40: =M22/$B$35 -> 0.18521521
A41: Leveraged Cash Flow | B41: =B33+B38*(B17<=$D$6) -> -1.0696049e+09 | C41: =C33+C38*(C17<=$D$6) -> 41812835 | D41: =D33+D38*(D17<=$D$6) -> 65693328 | E41: =E33+E38*(E17<=$D$6) -> 85197940 | F41: =F33+F38*(F17<=$D$6) -> 90801618 | G41: =G33+G38*(G17<=$D$6) -> 95901412 | H41: =H33+H38*(H17<=$D$6) -> 12279767 | I41: =I33+I38*(I17<=$D$6) -> 94606883 | ... M41: =M33+M38*(M17<=$D$6) -> 0
A42: Cash on Cash | C42: =((C36+C29)/-$B$41)*(C17<=$D$13) -> 0.03909185 | D42: =((D36+D29)/-$B$41)*(D17<=$D$13) -> 0.061418312 | E42: =((E36+E29)/-$B$41)*(E17<=$D$13) -> 0.079653654 | F42: =((F36+F29)/-$B$41)*(F17<=$D$13) -> 0.084892671 | G42: =((G36+G29)/-$B$41)*(G17<=$D$13) -> 0.089660594 | H42: =((H36+H29)/-$B$41)*(H17<=$D$13) -> 0.011480657 | I42: =((I36+I29)/-$B$41)*(I17<=$D$13) -> 0.088450306 | J42: =((J36+J29)/-$B$41)*(J17<=$D$13) -> 0.091337418 | ... M42: =((M36+M29)/-$B$41)*(M17<=$D$13) -> 0
A44: SOURCES AND USES | E44: SENSITIVITIES
A45: Sources | B45: % | C45: Amount | E45: PURCHASE PRICE | F45: ="Unlevered IRR & Equity Multiple " -> Unlevered IRR & Equity Multiple | J45: ="Levered IRR & Equity Multiple " -> Levered IRR & Equity Multiple | S45: UL Hold Period Sensitivity | Y45: L Hold Period Sensitivity
A46: Debt | B46: =C46/$C$49 -> 0.44430391 | C46: =D12 -> 1.0696049e+09 | F46: =T46 -> 3 | G46: =U46 -> 5 | H46: =V46 -> 7 | I46: =W46 -> 10 | J46: =Z46 -> 3 | K46: =AA46 -> 5 | L46: =AB46 -> 7 | M46: =AC46 -> 10 | S46: =TEXT(M4,"0.00%")&" - "&TEXT(M5,"0.00x") -> 8.36% - 1.90x | T46: =W46-7 -> 3 | U46: =W46-5 -> 5 | V46: =W46-3 -> 7 | W46: 10 | Y46: =TEXT(M7,"0.00%")&" - "&TEXT(M8,"0.00x") -> 9.53% - 2.13x | Z46: =AC46-7 -> 3 | AA46: =AC46-5 -> 5 | AB46: =AC46-3 -> 7 | AC46: 10
A47: Equity | B47: =C47/$C$49 -> 0.44430391 | C47: =B5-C46 -> 1.0696049e+09 | E47: =TEXT(S47/1000000,"$#,000")&"B - "&TEXT(R47,"0.00%")&" Going-In Cap" -> $2,339B - 7.68% Going-In Cap | F47: =T47 -> 7.24% - 1.22x | G47: =U47 -> 5.05% - 1.25x | H47: =V47 -> 6.36% - 1.45x | I47: =W47 -> 7.11% - 1.74x | J47: =Z47 -> 10.05% - 1.32x | K47: =AA47 -> 4.34% - 1.22x | L47: =AB47 -> 6.26% - 1.46x | M47: =AC47 -> 7.23% - 1.80x | R47: =$B$9/S47 -> 0.076795224 | S47: =S48+$F$52 -> 2339209844 | T47: 7.24% - 1.22x | U47: 5.05% - 1.25x | V47: 6.36% - 1.45x | W47: 7.11% - 1.74x | Y47: =Y48+$F$52 -> 2339209844 | Z47: 10.05% - 1.32x | AA47: 4.34% - 1.22x | AB47: 6.26% - 1.46x | AC47: 7.23% - 1.80x
A48: Cash Flow | B48: =C48/$C$49 -> 0.11139218 | C48: =C54-SUM(C46:C47) -> 268162461 | E48: =TEXT(S48/1000000,"$#,000")&"B - "&TEXT(R48,"0.00%")&" Going-In Cap" -> $2,239B - 8.02% Going-In Cap | F48: =T48 -> 8.90% - 1.28x | G48: =U48 -> 6.09% - 1.30x | H48: =V48 -> 7.15% - 1.51x | I48: =W48 -> 7.72% - 1.82x | J48: =Z48 -> 13.12% - 1.43x | K48: =AA48 -> 6.38% - 1.33x | L48: =AB48 -> 7.78% - 1.59x | M48: =AC48 -> 8.36% - 1.96x | R48: =$B$9/S48 -> 0.080224792 | S48: =S49+$F$52 -> 2239209844 | T48: 8.90% - 1.28x | U48: 6.09% - 1.30x | V48: 7.15% - 1.51x | W48: 7.72% - 1.82x | Y48: =Y49+$F$52 -> 2239209844 | Z48: 13.12% - 1.43x | AA48: 6.38% - 1.33x | AB48: 7.78% - 1.59x | AC48: 8.36% - 1.96x
...

Sheet Observatory Analysis
A1: OBSERVATION DECK ANALYSIS INPUTS
A2: Revenue Est. Ending 2023 | B2: 129400000 | C2: Hold Period | D2: ='Building Analysis'!D6 -> 10
A3: Avg Growth Rate | B3: =AVERAGEIF($C$8:$M$8,"<="&$D$2,$C$10:$M$10) -> 0.02 | C3: Operating Expenses | D3: 0.3
A4: Discount Rate | B4: 0.09 | C4: Exit Cap Rate | D4: 0.08
A5: Observatory PV | B5: =SUM(C18:M18) -> 1.2349265e+09 | C5: Exit Value | D5: =INDEX($B$13:$M$13,MATCH($D$2+1,$B$8:$M$8,0))/D4 -> 1.4078106e+09
A6: Going-In Cap Rate | B6: =C13/B5 -> 0.074815464
B8: =Proforma!E3 -> 0 | C8: =Proforma!F3 -> 1 | D8: =Proforma!G3 -> 2 | E8: =Proforma!H3 -> 3 | F8: =Proforma!I3 -> 4 | G8: =Proforma!J3 -> 5 | H8: =Proforma!K3 -> 6 | I8: =Proforma!L3 -> 7 | ... M8: =Proforma!P3 -> 11
A9: YEAR ENDING | B9: =EOMONTH(C9,-12) -> 45291 | C9: =Proforma!F4 -> 45657 | D9: =Proforma!G4 -> 46022 | E9: =Proforma!H4 -> 46387 | F9: =Proforma!I4 -> 46752 | G9: =Proforma!J4 -> 47118 | H9: =Proforma!K4 -> 47483 | I9: =Proforma!L4 -> 47848 | J9: =Proforma!M4 -> 48213 | ... M9: =Proforma!P4 -> 49309
A10: Growth Rate | C10: 0.02 | D10: 0.02 | E10: 0.02 | F10: 0.02 | G10: 0.02 | H10: 0.02 | I10: 0.02 | J10: 0.02 | K10: 0.02 | L10: 0.02 | M10: 0.02
A11: OBSERVATORY REVENUE | C11: =$B$2*(1+C10) -> 131988000 | D11: =C11*(1+D10) -> 134627760 | E11: =D11*(1+E10) -> 1.3732032e+08 | F11: =E11*(1+F10) -> 1.4006672e+08 | G11: =F11*(1+G10) -> 1.4286806e+08 | H11: =G11*(1+H10) -> 1.4572542e+08 | I11: =H11*(1+I10) -> 1.4863993e+08 | J11: =I11*(1+J10) -> 1.5161272e+08 | K11: =J11*(1+K10) -> 1.5464498e+08 | ... M11: =L11*(1+M10) -> 1.6089264e+08
A12: OPERATING EXPENSES | C12: =C11*$D$3 -> 39596400 | D12: =D11*$D$3 -> 40388328 | E12: =E11*$D$3 -> 41196095 | F12: =F11*$D$3 -> 42020016 | G12: =G11*$D$3 -> 42860417 | H12: =H11*$D$3 -> 43717625 | I12: =I11*$D$3 -> 44591978 | J12: =J11*$D$3 -> 45483817 | ... M12: =M11*$D$3 -> 48267791
A13: NOI | C13: =C11-C12 -> 92391600 | D13: =D11-D12 -> 94239432 | E13: =E11-E12 -> 96124221 | F13: =F11-F12 -> 98046705 | G13: =G11-G12 -> 1.0000764e+08 | H13: =H11-H12 -> 1.0200779e+08 | I13: =I11-I12 -> 1.0404795e+08 | J13: =J11-J12 -> 1.0612891e+08 | ... M13: =M11-M12 -> 1.1262484e+08
A14: Reversion | B14: =$D$5*(B8=$D$2) -> 0 | C14: =$D$5*(C8=$D$2) -> 0 | D14: =$D$5*(D8=$D$2) -> 0 | E14: =$D$5*(E8=$D$2) -> 0 | F14: =$D$5*(F8=$D$2) -> 0 | G14: =$D$5*(G8=$D$2) -> 0 | H14: =$D$5*(H8=$D$2) -> 0 | I14: =$D$5*(I8=$D$2) -> 0 | ... M14: =$D$5*(M8=$D$2) -> 0
A16: NOI PRESENT VALUE | C16: =(C13/(1+$B$4)^C$8)*(C8<=$D$2) -> 84762936 | D16: =(D13/(1+$B$4)^D$8)*(D8<=$D$2) -> 79319444 | E16: =(E13/(1+$B$4)^E$8)*(E8<=$D$2) -> 74225535 | F16: =(F13/(1+$B$4)^F$8)*(F8<=$D$2) -> 69458758 | G16: =(G13/(1+$B$4)^G$8)*(G8<=$D$2) -> 64998104 | H16: =(H13/(1+$B$4)^H$8)*(H8<=$D$2) -> 60823913 | I16: =(I13/(1+$B$4)^I$8)*(I8<=$D$2) -> 56917791 | J16: =(J13/(1+$B$4)^J$8)*(J8<=$D$2) -> 53262520 | ... M16: =(M13/(1+$B$4)^M$8)*(M8<=$D$2) -> 0
A17: REVERSION PRESENT VALUE | C17: =C14/(1+$B$4)^C$8 -> 0 | D17: =D14/(1+$B$4)^D$8 -> 0 | E17: =E14/(1+$B$4)^E$8 -> 0 | F17: =F14/(1+$B$4)^F$8 -> 0 | G17: =G14/(1+$B$4)^G$8 -> 0 | H17: =H14/(1+$B$4)^H$8 -> 0 | I17: =I14/(1+$B$4)^I$8 -> 0 | J17: =J14/(1+$B$4)^J$8 -> 0 | ... M17: =M14/(1+$B$4)^M$8 -> 0
A18: TOTAL PRESENT VALUE | C18: =SUM(C16:C17) -> 84762936 | D18: =SUM(D16:D17) -> 79319444 | E18: =SUM(E16:E17) -> 74225535 | F18: =SUM(F16:F17) -> 69458758 | G18: =SUM(G16:G17) -> 64998104 | H18: =SUM(H16:H17) -> 60823913 | I18: =SUM(I16:I17) -> 56917791 | J18: =SUM(J16:J17) -> 53262520 | ... M18: =SUM(M16:M17) -> 0
A46: FOR CHART
A47: YR | B47: Historic Revenue | C47: Projected Revenue
A48: 2001 | B48: 25
A49: =A48+1 -> 2002 | B49: 29.6
A50: =A49+1 -> 2003 | B50: 33.4
A51: =A50+1 -> 2004 | B51: 40
A52: =A51+1 -> 2005 | B52: 50.1
A53: =A52+1 -> 2006 | B53: 56.3
A54: =A53+1 -> 2007 | B54: 62.9
A55: =A54+1 -> 2008 | B55: 72.2
A56: =A55+1 -> 2009 | B56: 71.6
A57: =A56+1 -> 2010 | B57: 78.9
A58: =A57+1 -> 2011 | B58: 80.6
A59: =A58+1 -> 2012 | B59: 91.9
A60: =A59+1 -> 2013 | B60: 101.8
... A69: =A68+1 -> 2022 | B69: 61.8
A70: =A69+1 -> 2023 | C70: =B2/1000000 -> 129.4
A71: =A70+1 -> 2024 | C71: =C11/1000000 -> 131.988
A72: =A71+1 -> 2025 | C72: =D11/1000000 -> 134.62776
A73: =A72+1 -> 2026 | C73: =E11/1000000 -> 137.32032
A74: =A73+1 -> 2027 | C74: =F11/1000000 -> 140.06672
A75: =A74+1 -> 2028 | C75: =G11/1000000 -> 142.86806
A76: =A75+1 -> 2029 | C76: =H11/1000000 -> 145.72542
A77: =A76+1 -> 2030 | C77: =I11/1000000 -> 148.63993
...

Sheet Building Analysis
A2: PROPERTY INFORMATION | F2: REVERSION CALCULATION | K2: SOURCES AND USES
A3: Property | B3: ='Property Summary'!B3 -> The Empire State Building | C3: Address | D3: ='Property Summary'!D3 -> 350 Fifth Avenue | F3: Sale Year | G3: =D6 -> 10 | I3: =INDEX(Proforma!$E$4:$P$4,MATCH(G3,Proforma!$E$3:$P$3,0)) -> 48944 | K3: Sources | L3: % | M3: Amount
A4: RBA | B4: ='Property Summary'!B4 -> 2808567 | C4: City, State | D4: ='Property Summary'!D4 -> New York, NY | H4: PSF | I4: $
A5: Purchase Price | B5: 904283329 | C5: Exit Cap Rate | D5: 0.07 | F5: Forward NOI | H5: =I5/$B$4 -> 30.436252 | I5: =INDEX(Proforma!$E$37:$P$37,MATCH($G$3+1,Proforma!$E$3:$P$3,0)) -> 85482252 | K5: Equity | L5: =M5/$M$7 -> 0.77127944 | M5: =B5-M4 -> 904283329
A6: Purchase Price (PSF) | B6: =B5/B4 -> 321.97321 | C6: Hold Period | D6: ='Property Summary'!D6 -> 10 | F6: Reversion Vacancy | G6: 0.1 | H6: =I6/$B$4 -> -3.0436252 | I6: =-I5*G6 -> -8548225.2 | K6: Cash Flow | L6: =M6/$M$7 -> 0.22872056 | M6: =M12-SUM(M4:M5) -> 268162461
A7: Going-In Cap Rate | B7: =B9/B5 -> 0.096483636 | C7: Analysis Start Date | D7: ='Property Summary'!D7 -> 45292 | F7: NOI to Capitalize | H7: =I7/$B$4 -> 27.392626 | I7: =SUM(I5:I6) -> 76934027 | K7: Total Sources | L7: =SUM(L4:L6) -> 1 | M7: =SUM(M4:M6) -> 1172445790
A8: In Place Occupancy | B8: =Proforma!F6 -> 0.88421604 | C8: Analysis End Date | D8: =EOMONTH(D7-1,D6*12) -> 48944 | F8: Divide by Exit Cap Rate | I8: =D5 -> 0.07 | K8: Uses | L8: % | M8: Amount
A9: YR1 NOI | B9: =Proforma!F37 -> 87248544 | C9: ="Exit Forward NOI - YR"&D6&"" -> Exit Forward NOI - YR10 | D9: =INDEX(Proforma!$E$37:$P$37,MATCH(D6,Proforma!$E$3:$P$3,0)) -> 85461331 | F9: Gross Sales Price | H9: =I9/$B$4 -> 391.32324 | I9: =I7/I8 -> 1.0990575e+09 | K9: Purchase Price | L9: =M9/$M$12 -> 0.77127944 | M9: =-B33 -> 904283329
F10: Selling Expense | G10: ='Property Summary'!$G$6 -> 0.02 | H10: =I10/$B$4 -> -7.8264647 | I10: =-I9*G10 -> -21981151 | K10: Capital Improvements | L10: =M10/$M$12 -> 0.22872056 | M10: =-SUMIF($C$17:$M$17,"<="&G3,C27:M27) -> 268162461
F11: Net Sales Price | H11: =I11/$B$4 -> 383.49677 | I11: =SUM(I9:I10) -> 1.0770764e+09
A12: RETURN SUMMARY | F12: ="PV of Net Sales Price @ "&TEXT(C14,"0.00%")&" Discount Rate" -> PV of Net Sales Price @ 7.72% Discount Rate | H12: =I12/$B$4 -> 182.36476 | I12: =I11/(1+C14)^G3 -> 5.1218363e+08 | K12: Total Uses | L12: =SUM(L9:L11) -> 1 | M12: =SUM(M9:M11) -> 1172445790
A13: Deal Unleveraged Profit | B13: =C13/$B$4 -> 276.48931 | C13: =Proforma!C62 -> 7.7653875e+08
A14: Deal Unleveraged IRR | C14: =Proforma!C63 -> 0.07716462
A15: Deal Unleveraged Multiple | C15: =Proforma!C64 -> 1.8546372
A17: CASH FLOW SUMMARY | B17: =Proforma!E3 -> 0 | C17: =Proforma!F3 -> 1 | D17: =Proforma!G3 -> 2 | E17: =Proforma!H3 -> 3 | F17: =Proforma!I3 -> 4 | G17: =Proforma!J3 -> 5 | H17: =Proforma!K3 -> 6 | I17: =Proforma!L3 -> 7 | ... M17: =Proforma!P3 -> 11
A18: Year Ending | B18: =Proforma!E4 -> 45292 | C18: =Proforma!F4 -> 45657 | D18: =Proforma!G4 -> 46022 | E18: =Proforma!H4 -> 46387 | F18: =Proforma!I4 -> 46752 | G18: =Proforma!J4 -> 47118 | H18: =Proforma!K4 -> 47483 | I18: =Proforma!L4 -> 47848 | ... M18: =Proforma!P4 -> 49309
A19: Average Occupancy | B19: - | C19: =Proforma!F6 -> 0.88421604 | D19: =Proforma!G6 -> 0.91714992 | E19: =Proforma!H6 -> 0.97081074 | F19: =Proforma!I6 -> 0.97584097 | G19: =Proforma!J6 -> 0.96203111 | H19: =Proforma!K6 -> 0.90869332 | I19: =Proforma!L6 -> 0.99193005 | J19: =Proforma!M6 -> 0.99292729 | ... M19: =Proforma!P6 -> 0.96345829
A20: Effective Gross Income | B20: 0 | C20: =Proforma!F27 -> 174227252 | D20: =Proforma!G27 -> 180905314 | E20: =Proforma!H27 -> 187616360 | F20: =Proforma!I27 -> 192115860 | G20: =Proforma!J27 -> 191791166 | H20: =Proforma!K27 -> 166705609 | I20: =Proforma!L27 -> 179754367 | J20: =Proforma!M27 -> 183262071 | ... M20: =Proforma!P27 -> 192163767
A21: Operating Expenses | B21: =Proforma!E35 -> 0 | C21: =Proforma!F35 -> 86978708 | D21: =Proforma!G35 -> 89252791 | E21: =Proforma!H35 -> 91859738 | F21: =Proforma!I35 -> 93789061 | G21: =Proforma!J35 -> 95344616 | H21: =Proforma!K35 -> 95614796 | I21: =Proforma!L35 -> 99042713 | ... M21: =Proforma!P35 -> 106681515
A22: Net Operating Income | B22: 0 | C22: =C20-C21 -> 87248544 | D22: =D20-D21 -> 91652523 | E22: =E20-E21 -> 95756622 | F22: =F20-F21 -> 98326799 | G22: =G20-G21 -> 96446550 | H22: =H20-H21 -> 71090813 | I22: =I20-I21 -> 80711654 | J22: =J20-J21 -> 82226166 | ... M22: =M20-M21 -> 85482252
A23: NOI Growth | B23: - | C23: 0 | D23: =(D22-C22)/C22 -> 0.050476246 | E23: =(E22-D22)/D22 -> 0.044778898 | F23: =(F22-E22)/E22 -> 0.026840723 | G23: =(G22-F22)/F22 -> -0.019122447 | H23: =(H22-G22)/G22 -> -0.26289937 | I23: =(I22-H22)/H22 -> 0.13533171 | J23: =(J22-I22)/I22 -> 0.018764477 | K23: =(K22-J22)/J22 -> 0.0092549372 | ... M23: =(M22-L22)/L22 -> 0.00024480077
A25: Leasing Costs | B25: =-Proforma!E42 -> 0 | C25: =-Proforma!F42 -> -52346631 | D25: =-Proforma!G42 -> -34717449 | E25: =-Proforma!H42 -> -21201215 | F25: =-Proforma!I42 -> -15202057 | G25: =-Proforma!J42 -> -12932417 | H25: =-Proforma!K42 -> -75397937 | I25: =-Proforma!L42 -> -4731266 | ... M25: =-Proforma!P42 -> -18345095
A26: Building Capital Expenditures | B26: =-Proforma!E43 -> 0 | C26: =-Proforma!F43 -> -10608333 | D26: =-Proforma!G43 -> -10608833 | E26: =-Proforma!H43 -> -10609343 | F26: =-Proforma!I43 -> -4976530 | G26: =-Proforma!J43 -> -2227061 | H26: =-Proforma!K43 -> -27602 | I26: =-Proforma!L43 -> -28154 | ... M26: =-Proforma!P43 -> -30475
A27: Total Capital Improvements | B27: =SUM(B25:B26) -> 0 | C27: =SUM(C25:C26) -> -62954964 | D27: =SUM(D25:D26) -> -45326282 | E27: =SUM(E25:E26) -> -31810558 | F27: =SUM(F25:F26) -> -20178587 | G27: =SUM(G25:G26) -> -15159478 | H27: =SUM(H25:H26) -> -75425539 | I27: =SUM(I25:I26) -> -4759420 | ... M27: =SUM(M25:M26) -> -18375570
A29: Cash Flow Before Debt Service | C29: =(C22+C27)*(C17<=$D$6) -> 24293580 | D29: =(D22+D27)*(D17<=$D$6) -> 46326241 | E29: =(E22+E27)*(E17<=$D$6) -> 63946064 | F29: =(F22+F27)*(F17<=$D$6) -> 78148212 | G29: =(G22+G27)*(G17<=$D$6) -> 81287072 | H29: =(H22+H27)*(H17<=$D$6) -> -4334726 | I29: =(I22+I27)*(I17<=$D$6) -> 75952234 | J29: =(J22+J27)*(J17<=$D$6) -> 76959344 | ... M29: =(M22+M27)*(M17<=$D$6) -> 0
A31: ="Net Reversion @ "&TEXT($D$5,"0.00%")&" Exit Cap" -> Net Reversion @ 7.00% Exit Cap | C31: =Proforma!F47 -> 0 | D31: =Proforma!G47 -> 0 | E31: =Proforma!H47 -> 0 | F31: =Proforma!I47 -> 0 | G31: =Proforma!J47 -> 0 | H31: =Proforma!K47 -> 0 | I31: =Proforma!L47 -> 0 | J31: =Proforma!M47 -> 0 | ... M31: =Proforma!P47 -> 0
A33: Unleveraged Cash Flow | B33: =-B5 -> -904283329 | C33: =SUM(C29,C31)*(C17<=$D$6) -> 24293580 | D33: =SUM(D29,D31)*(D17<=$D$6) -> 46326241 | E33: =SUM(E29,E31)*(E17<=$D$6) -> 63946064 | F33: =SUM(F29,F31)*(F17<=$D$6) -> 78148212 | G33: =SUM(G29,G31)*(G17<=$D$6) -> 81287072 | H33: =SUM(H29,H31)*(H17<=$D$6) -> -4334726 | I33: =SUM(I29,I31)*(I17<=$D$6) -> 75952234 | J33: =SUM(J29,J31)*(J17<=$D$6) -> 76959344 | ... M33: =SUM(M29,M31)*(M17<=$D$6) -> 0
A35: SENSITIVITIES | G35: RETURN METRICS
A36: PURCHASE PRICE | B36: ="Unlevered IRR & Equity Multiple - @ "&TEXT($D$5,"0.00%")&" Exit Cap" -> Unlevered IRR & Equity Multiple - @ 7.00% Exit Cap | G36: Cap Rate | H36: Unlevered IRR | S36: UL Hold Period Sensitivity
B37: =T37 -> 3 | C37: =U37 -> 5 | D37: =V37 -> 7 | E37: =W37 -> 10 | G37: =C22/-B33 -> 0.096483636 | H37: =IRR(B33:M33) -> 0.07716462 | S37: =TEXT(C14,"0.00%")&" - "&TEXT(C15,"0.00x") -> 7.72% - 1.85x | T37: =W37-7 -> 3 | U37: =W37-5 -> 5 | V37: =W37-3 -> 7 | W37: 10
A38: =TEXT(S38/1000000,"$#,000")&"B - "&TEXT(R38,"0.00%")&" Going-In Cap" -> $906B - 9.63% Going-In Cap | B38: =T38 -> 15.31% - 1.52x | C38: =U38 -> 6.11% - 1.31x | D38: =V38 -> 7.32% - 1.55x | E38: =W38 -> 7.70% - 1.85x | R38: =$B$9/S38 -> 0.096333861 | S38: =S39+$B$43 -> 905689265 | T38: 15.31% - 1.52x | U38: 6.11% - 1.31x | V38: 7.32% - 1.55x | W38: 7.70% - 1.85x
A39: =TEXT(S39/1000000,"$#,000")&"B - "&TEXT(R39,"0.00%")&" Going-In Cap" -> $806B - 10.83% Going-In Cap | B39: =T39 -> 20.04% - 1.70x | C39: =U39 -> 8.86% - 1.48x | D39: =V39 -> 9.42% - 1.74x | E39: =W39 -> 9.28% - 2.08x | R39: =$B$9/S39 -> 0.10829056 | S39: =S40+$B$43 -> 805689265 | T39: 20.04% - 1.70x | U39: 8.86% - 1.48x | V39: 9.42% - 1.74x | W39: 9.28% - 2.08x
A40: =TEXT(S40/1000000,"$#,000")&"B - "&TEXT(R40,"0.00%")&" Going-In Cap" -> $706B - 12.36% Going-In Cap | B40: =T40 -> 25.63% - 1.95x | C40: =U40 -> 12.09% - 1.69x | D40: =V40 -> 11.87% - 1.98x | E40: =W40 -> 11.14% - 2.37x | R40: =$B$9/S40 -> 0.12363592 | S40: 705689265 | T40: 25.63% - 1.95x | U40: 12.09% - 1.69x | V40: 11.87% - 1.98x | W40: 11.14% - 2.37x
A41: =TEXT(S41/1000000,"$#,000")&"B - "&TEXT(R41,"0.00%")&" Going-In Cap" -> $606B - 14.40% Going-In Cap | B41: =T41 -> 32.43% - 2.27x | C41: =U41 -> 15.96% - 1.96x | D41: =V41 -> 14.80% - 2.30x | E41: =W41 -> 13.37% - 2.76x | R41: =$B$9/S41 -> 0.14404836 | S41: =S40-$B$43 -> 605689265 | T41: 32.43% - 2.27x | U41: 15.96% - 1.96x | V41: 14.80% - 2.30x | W41: 13.37% - 2.76x
A42: =TEXT(S42/1000000,"$#,000")&"B - "&TEXT(R42,"0.00%")&" Going-In Cap" -> $506B - 17.25% Going-In Cap | B42: =T42 -> 40.96% - 2.72x | C42: =U42 -> 20.74% - 2.35x | D42: =V42 -> 18.42% - 2.76x | E42: =W42 -> 16.14% - 3.30x | R42: =$B$9/S42 -> 0.17253391 | S42: =S41-$B$43 -> 505689265 | T42: 40.96% - 2.72x | U42: 20.74% - 2.35x | V42: 18.42% - 2.76x | W42: 16.14% - 3.30x
A43: Pricing Sensitivity: | B43: 100000000

Sheet ARGUS MLAs
A1: ARGUS INPUT UNDERWRITING ASSUMPTIONS
A3: Property Assumptions | K3: MARKET LEASING PROFILE ASSUMPTIONS | M3: MLA 1 | N3: MLA 2 | O3: MLA 3 | P3: MLA 4 | Q3: MLA 5
A4: Rentable Building Area | I4: 2808567 | K4: Market Inflation | M4: High Rise Office | N4: Mid Rise Office | O4: Low Rise Office | P4: Retail | Q4: Antenna
A5: Vacant Square Feet | I5: 455384 | K5: 45657 | L5: 0 | M5: 70 | N5: 65 | O5: 60 | P5: 70 | Q5: 550
A6: Current Occupancy | I6: =I4-I5 -> 2353183 | K6: =EOMONTH(K5,12) -> 46022 | L6: 0 | M6: =M5*(1+$L6) -> 70 | N6: =N5*(1+$L6) -> 65 | O6: =O5*(1+$L6) -> 60 | P6: =P5*(1+$L6) -> 70 | Q6: =Q5*(1+$L6) -> 550
K7: =EOMONTH(K6,12) -> 46387 | L7: 0 | M7: =M6*(1+$L7) -> 70 | N7: =N6*(1+$L7) -> 65 | O7: =O6*(1+$L7) -> 60 | P7: =P6*(1+$L7) -> 70 | Q7: =Q6*(1+$L7) -> 550
A8: Global Assumptions | K8: =EOMONTH(K7,12) -> 46752 | L8: 0.01 | M8: =M7*(1+$L8) -> 70.7 | N8: =N7*(1+$L8) -> 65.65 | O8: =O7*(1+$L8) -> 60.6 | P8: =P7*(1+$L8) -> 70.7 | Q8: =Q7*(1+$L8) -> 555.5
A9: Analysis Begin Date | I9: 45292 | K9: =EOMONTH(K8,12) -> 47118 | L9: 0.01 | M9: =M8*(1+$L9) -> 71.407 | N9: =N8*(1+$L9) -> 66.3065 | O9: =O8*(1+$L9) -> 61.206 | P9: =P8*(1+$L9) -> 71.407 | Q9: =Q8*(1+$L9) -> 561.055
A10: Analysis End Date | I10: =EOMONTH(I9,120) -> 48975 | K10: =EOMONTH(K9,12) -> 47483 | L10: 0.015 | M10: =M9*(1+$L10) -> 72.478105 | N10: =N9*(1+$L10) -> 67.301097 | O10: =O9*(1+$L10) -> 62.12409 | P10: =P9*(1+$L10) -> 72.478105 | Q10: =Q9*(1+$L10) -> 569.47082
A11: Term of Analysis | I11: 10 | K11: =EOMONTH(K10,12) -> 47848 | L11: 0.02 | M11: =M10*(1+$L11) -> 73.927667 | N11: =N10*(1+$L11) -> 68.647119 | O11: =O10*(1+$L11) -> 63.366572 | P11: =P10*(1+$L11) -> 73.927667 | Q11: =Q10*(1+$L11) -> 580.86024
A12: General Inflation Rate | I12: 0.03 | K12: =EOMONTH(K11,12) -> 48213 | L12: 0.025 | M12: =M11*(1+$L12) -> 75.775859 | N12: =N11*(1+$L12) -> 70.363297 | O12: =O11*(1+$L12) -> 64.950736 | P12: =P11*(1+$L12) -> 75.775859 | Q12: =Q11*(1+$L12) -> 595.38175
A13: Market Inflation Rate | I13: 0.015 | K13: =EOMONTH(K12,12) -> 48579 | L13: 0.025 | M13: =M12*(1+$L13) -> 77.670255 | N13: =N12*(1+$L13) -> 72.12238 | O13: =O12*(1+$L13) -> 66.574504 | P13: =P12*(1+$L13) -> 77.670255 | Q13: =Q12*(1+$L13) -> 610.26629
A14: Expense Inflation Rate | I14: 0.02 | K14: =EOMONTH(K13,12) -> 48944 | L14: 0.03 | M14: =M13*(1+$L14) -> 80.000363 | N14: =N13*(1+$L14) -> 74.286051 | O14: =O13*(1+$L14) -> 68.57174 | P14: =P13*(1+$L14) -> 80.000363 | Q14: =Q13*(1+$L14) -> 628.57428
A15: General Vacancy | I15: 0.1 | K15: Term
A16: Credit Loss | I16: 0.01 | K16: Lease Term | M16: 10 | N16: 10 | O16: 10 | P16: 7 | Q16: 5
A17: Management Fees - YR1 | I17: 0.03 | K17: Renewal Probability | M17: 0.6 | N17: 0.6 | O17: 0.6 | P17: 0.6 | Q17: 0.7
A18: Capital Reserve | K18: Downtime
K19: Months Vacant | M19: 12 | N19: 12 | O19: 12 | P19: 6 | Q19: 6
A20: Year 1 Operating Expenses | K20: Weighted Average | M20: =(M19*M$17)+(0*(1-M$17)) -> 7.2 | N20: =(N19*N$17)+(0*(1-N$17)) -> 7.2 | O20: =(O19*O$17)+(0*(1-O$17)) -> 7.2 | P20: =(P19*P$17)+(0*(1-P$17)) -> 3.6 | Q20: =(Q19*Q$17)+(0*(1-Q$17)) -> 4.2
A21: Real estate taxes | H21: =I21/$I$6 -> 18.281621 | I21: 43020000 | K21: Rent
A22: Insurance | H22: =I22/$I$6 -> 1.4441571 | I22: 3398366 | K22: Market Rent | M22: 70 | N22: 65 | O22: 60 | P22: 70 | Q22: 550
A23: Utilities | H23: =I23/$I$6 -> 2.3322751 | I23: 5488270 | K23: Rent Steps | M23: 0.01 | N23: 0.01 | O23: 0.01 | P23: 0.01
A24: Repairs and maint. | H24: =I24/$I$6 -> 3.9670094 | I24: 9335099 | K24: Free Rent
A25: Management fees | H25: =I25/$I$6 -> 2.2211694 | I25: 5226818 | K25: New | M25: 2 | N25: 4 | O25: 4 | P25: 2 | Q25: 0
A26: Payroll and benefits | H26: =I26/$I$6 -> 3.2821752 | I26: 7723559 | K26: Renew | M26: 2 | N26: 2 | O26: 2 | P26: 2 | Q26: 0
A27: Adv. and marketing | H27: =I27/$I$6 -> 0.60768754 | I27: 1430000 | K27: Weighted Average | M27: =(M26*M$17)+(M25*(1-M$17)) -> 2 | N27: =(N26*N$17)+(N25*(1-N$17)) -> 2.8 | O27: =(O26*O$17)+(O25*(1-O$17)) -> 2.8 | P27: =(P26*P$17)+(P25*(1-P$17)) -> 2 | Q27: =(Q26*Q$17)+(Q25*(1-Q$17)) -> 0
A28: Security | H28: =I28/$I$6 -> 2.259993 | I28: 5318177 | K28: Tenant Improvements
A29: Janitorial and cleaning | H29: =I29/$I$6 -> 2.5660643 | I29: 6038419 | K29: New | M29: 100 | N29: 75 | O29: 60 | P29: 45 | Q29: 0
H30: =I30/$I$6 -> 0 | K30: Renew | M30: 50 | N30: 40 | O30: 30 | P30: 25 | Q30: 0
A31: Total Year 1 Expenses | H31: =SUM(H21:H30) -> 36.962152 | I31: =SUM(I21:I30) -> 86978708 | K31: Weighted Average | M31: =(M30*M$17)+(M29*(1-M$17)) -> 70 | N31: =(N30*N$17)+(N29*(1-N$17)) -> 54 | O31: =(O30*O$17)+(O29*(1-O$17)) -> 42 | P31: =(P30*P$17)+(P29*(1-P$17)) -> 33 | Q31: =(Q30*Q$17)+(Q29*(1-Q$17)) -> 0
K32: Leasing Commissions
A33: Vacant Suite Lease-Up Assumptions | K33: New | M33: 0.06 | N33: 0.06 | O33: 0.06 | P33: 0.06
A34: Type | C34: Floor | F34: Square Feet | I34: Category | K34: Renew | M34: 0.03 | N34: 0.03 | O34: 0.03 | P34: 0.03
A35: Retail | C35: Ground | F35: 15389 | I35: Retail | K35: Weighted Average | M35: =(M34*M$17)+(M33*(1-M$17)) -> 0.042 | N35: =(N34*N$17)+(N33*(1-N$17)) -> 0.042 | O35: =(O34*O$17)+(O33*(1-O$17)) -> 0.042 | P35: =(P34*P$17)+(P33*(1-P$17)) -> 0.042 | Q35: =(Q34*Q$17)+(Q33*(1-Q$17)) -> 0
A36: Retail | C36: Ground | F36: 2758 | I36: Retail | K36: Expense Recovery
A37: Retail | C37: Ground | F37: 5561 | I37: Retail | K37: Recovery Type | M37: BASE YR STOP | N37: BASE YR STOP | O37: BASE YR STOP | P37: NET | Q37: -
A38: Office - Low | C38: 5th | F38: 35110 | I38: Big Block | K38: Assigned Tenants1
A39: Office - Low | C39: 7th | F39: 52116 | I39: Big Block | K39: Tenants | M39: FDIC | N39: LinkedIn | O39: Revolution LLC | P39: Starbucks | Q39: Broadcast 1
A40: Office - Low | C40: 8th | F40: 51703 | I40: Big Block | M40: COTY, Inc. | N40: Human Rights Watch, Inc. | O40: Phillips Engineering | P40: ABC Global | Q40: Broadcast 2
A41: Office - Low | C41: 9th | F41: 51988 | I41: Big Block | M41: Shutterstock | N41: Global Brands Group | O41: Chattaway Partners | P41: Pacific Century Cyberworks | Q41: Broadcast 3
...

Sheet Proforma
A1: ='Building Analysis'!B3 -> The Empire State Building
A2: ='Building Analysis'!B4 -> 2808567
E3: 0 | F3: 1 | G3: =F3+1 -> 2 | H3: =G3+1 -> 3 | I3: =H3+1 -> 4 | J3: =I3+1 -> 5 | K3: =J3+1 -> 6 | L3: =K3+1 -> 7 | M3: =L3+1 -> 8 | N3: =M3+1 -> 9 | ... P3: =O3+1 -> 11
E4: ='Building Analysis'!$D$7 -> 45292 | F4: =EOMONTH(E4,11) -> 45657 | G4: =EOMONTH(F4,12) -> 46022 | H4: =EOMONTH(G4,12) -> 46387 | I4: =EOMONTH(H4,12) -> 46752 | J4: =EOMONTH(I4,12) -> 47118 | K4: =EOMONTH(J4,12) -> 47483 | L4: =EOMONTH(K4,12) -> 47848 | M4: =EOMONTH(L4,12) -> 48213 | N4: =EOMONTH(M4,12) -> 48579 | ... P4: =EOMONTH(O4,12) -> 49309
A6: Average Occupancy Percentage | F6: =SUMIFS(INDEX('Argus Cash Flow Drop'!$B$1:$Z$98,0,MATCH(Proforma!F$3,'Argus Cash Flow Drop'!$B$1:$Z$1,0)),'Argus Cash Flow Drop'!$B$1:$B$98,Proforma!$A6) -> 0.88421604 | G6: =SUMIFS(INDEX('Argus Cash Flow Drop'!$B$1:$Z$98,0,MATCH(Proforma!G$3,'Argus Cash Flow Drop'!$B$1:$Z$1,0)),'Argus Cash Flow Drop'!$B$1:$B$98,Proforma!$A6) -> 0.91714992 | H6: =SUMIFS(INDEX('Argus Cash Flow Drop'!$B$1:$Z$98,0,MATCH(Proforma!H$3,'Argus Cash Flow Drop'!$B$1:$Z$1,0)),'Argus Cash Flow Drop'!$B$1:$B$98,Proforma!$A6) -> 0.97081074 | I6: =SUMIFS(INDEX('Argus Cash Flow Drop'!$B$1:$Z$98,0,MATCH(Proforma!I$3,'Argus Cash Flow Drop'!$B$1:$Z$1,0)),'Argus Cash Flow Drop'!$B$1:$B$98,Proforma!$A6) -> 0.97584097 | J6: =SUMIFS(INDEX('Argus Cash Flow Drop'!$B$1:$Z$98,0,MATCH(Proforma!J$3,'Argus Cash Flow Drop'!$B$1:$Z$1,0)),'Argus Cash Flow Drop'!$B$1:$B$98,Proforma!$A6) -> 0.96203111 | K6: =SUMIFS(INDEX('Argus Cash Flow Drop'!$B$1:$Z$98,0,MATCH(Proforma!K$3,'Argus Cash Flow Drop'!$B$1:$Z$1,0)),'Argus Cash Flow Drop'!$B$1:$B$98,Proforma!$A6) -> 0.90869332 | L6: =SUMIFS(INDEX('Argus Cash Flow Drop'!$B$1:$Z$98,0,MATCH(Proforma!L$3,'Argus Cash Flow Drop'!$B$1:$Z$1,0)),'Argus Cash Flow Drop'!$B$1:$B$98,Proforma!$A6) -> 0.99193005 | M6: =SUMIFS(INDEX('Argus Cash Flow Drop'!$B$1:$Z$98,0,MATCH(Proforma!M$3,'Argus Cash Flow Drop'!$B$1:$Z$1,0)),'Argus Cash Flow Drop'!$B$1:$B$98,Proforma!$A6) -> 0.99292729 | ... P6: =SUMIFS(INDEX('Argus Cash Flow Drop'!$B$1:$Z$98,0,MATCH(Proforma!P$3,'Argus Cash Flow Drop'!$B$1:$Z$1,0)),'Argus Cash Flow Drop'!$B$1:$B$98,Proforma!$A6) -> 0.96345829
A7: Vacant Area | F7: =SUMIFS(INDEX('Argus Cash Flow Drop'!$B$1:$Z$98,0,MATCH(Proforma!F$3,'Argus Cash Flow Drop'!$B$1:$Z$1,0)),'Argus Cash Flow Drop'!$B$1:$B$98,Proforma!$A7) -> 325187 | G7: =SUMIFS(INDEX('Argus Cash Flow Drop'!$B$1:$Z$98,0,MATCH(Proforma!G$3,'Argus Cash Flow Drop'!$B$1:$Z$1,0)),'Argus Cash Flow Drop'!$B$1:$B$98,Proforma!$A7) -> 232690 | H7: =SUMIFS(INDEX('Argus Cash Flow Drop'!$B$1:$Z$98,0,MATCH(Proforma!H$3,'Argus Cash Flow Drop'!$B$1:$Z$1,0)),'Argus Cash Flow Drop'!$B$1:$B$98,Proforma!$A7) -> 81980 | I7: =SUMIFS(INDEX('Argus Cash Flow Drop'!$B$1:$Z$98,0,MATCH(Proforma!I$3,'Argus Cash Flow Drop'!$B$1:$Z$1,0)),'Argus Cash Flow Drop'!$B$1:$B$98,Proforma!$A7) -> 67852 | J7: =SUMIFS(INDEX('Argus Cash Flow Drop'!$B$1:$Z$98,0,MATCH(Proforma!J$3,'Argus Cash Flow Drop'!$B$1:$Z$1,0)),'Argus Cash Flow Drop'!$B$1:$B$98,Proforma!$A7) -> 106638 | K7: =SUMIFS(INDEX('Argus Cash Flow Drop'!$B$1:$Z$98,0,MATCH(Proforma!K$3,'Argus Cash Flow Drop'!$B$1:$Z$1,0)),'Argus Cash Flow Drop'!$B$1:$B$98,Proforma!$A7) -> 256441 | L7: =SUMIFS(INDEX('Argus Cash Flow Drop'!$B$1:$Z$98,0,MATCH(Proforma!L$3,'Argus Cash Flow Drop'!$B$1:$Z$1,0)),'Argus Cash Flow Drop'!$B$1:$B$98,Proforma!$A7) -> 22665 | M7: =SUMIFS(INDEX('Argus Cash Flow Drop'!$B$1:$Z$98,0,MATCH(Proforma!M$3,'Argus Cash Flow Drop'!$B$1:$Z$1,0)),'Argus Cash Flow Drop'!$B$1:$B$98,Proforma!$A7) -> 19864 | ... P7: =SUMIFS(INDEX('Argus Cash Flow Drop'!$B$1:$Z$98,0,MATCH(Proforma!P$3,'Argus Cash Flow Drop'!$B$1:$Z$1,0)),'Argus Cash Flow Drop'!$B$1:$B$98,Proforma!$A7) -> 102630
A9: POTENTIAL GROSS REVENUE | C9: YR1 / SF
A10: Potential Base Rent | C10: =F10/$A$2/12 -> 5.7185232 | E10: 0 | F10: =SUMIFS(INDEX('Argus Cash Flow Drop'!$B$1:$Z$98,0,MATCH(Proforma!F$3,'Argus Cash Flow Drop'!$B$1:$Z$1,0)),'Argus Cash Flow Drop'!$B$1:$B$98,Proforma!$A10) -> 192730265 | G10: =SUMIFS(INDEX('Argus Cash Flow Drop'!$B$1:$Z$98,0,MATCH(Proforma!G$3,'Argus Cash Flow Drop'!$B$1:$Z$1,0)),'Argus Cash Flow Drop'!$B$1:$B$98,Proforma!$A10) -> 196665836 | H10: =SUMIFS(INDEX('Argus Cash Flow Drop'!$B$1:$Z$98,0,MATCH(Proforma!H$3,'Argus Cash Flow Drop'!$B$1:$Z$1,0)),'Argus Cash Flow Drop'!$B$1:$B$98,Proforma!$A10) -> 201172086 | I10: =SUMIFS(INDEX('Argus Cash Flow Drop'!$B$1:$Z$98,0,MATCH(Proforma!I$3,'Argus Cash Flow Drop'!$B$1:$Z$1,0)),'Argus Cash Flow Drop'!$B$1:$B$98,Proforma!$A10) -> 203672189 | J10: =SUMIFS(INDEX('Argus Cash Flow Drop'!$B$1:$Z$98,0,MATCH(Proforma!J$3,'Argus Cash Flow Drop'!$B$1:$Z$1,0)),'Argus Cash Flow Drop'!$B$1:$B$98,Proforma!$A10) -> 201866506 | K10: =SUMIFS(INDEX('Argus Cash Flow Drop'!$B$1:$Z$98,0,MATCH(Proforma!K$3,'Argus Cash Flow Drop'!$B$1:$Z$1,0)),'Argus Cash Flow Drop'!$B$1:$B$98,Proforma!$A10) -> 189739704 | L10: =SUMIFS(INDEX('Argus Cash Flow Drop'!$B$1:$Z$98,0,MATCH(Proforma!L$3,'Argus Cash Flow Drop'!$B$1:$Z$1,0)),'Argus Cash Flow Drop'!$B$1:$B$98,Proforma!$A10) -> 188872887 | M10: =SUMIFS(INDEX('Argus Cash Flow Drop'!$B$1:$Z$98,0,MATCH(Proforma!M$3,'Argus Cash Flow Drop'!$B$1:$Z$1,0)),'Argus Cash Flow Drop'!$B$1:$B$98,Proforma!$A10) -> 191192600 | ... P10: =SUMIFS(INDEX('Argus Cash Flow Drop'!$B$1:$Z$98,0,MATCH(Proforma!P$3,'Argus Cash Flow Drop'!$B$1:$Z$1,0)),'Argus Cash Flow Drop'!$B$1:$B$98,Proforma!$A10) -> 197724472
A11: Absorption & Turnover Vacancy | C11: =F11/$A$2/12 -> -0.59065035 | E11: 0 | F11: =SUMIFS(INDEX('Argus Cash Flow Drop'!$B$1:$Z$98,0,MATCH(Proforma!F$3,'Argus Cash Flow Drop'!$B$1:$Z$1,0)),'Argus Cash Flow Drop'!$B$1:$B$98,Proforma!$A11) -> -19906573 | G11: =SUMIFS(INDEX('Argus Cash Flow Drop'!$B$1:$Z$98,0,MATCH(Proforma!G$3,'Argus Cash Flow Drop'!$B$1:$Z$1,0)),'Argus Cash Flow Drop'!$B$1:$B$98,Proforma!$A11) -> -14667121 | H11: =SUMIFS(INDEX('Argus Cash Flow Drop'!$B$1:$Z$98,0,MATCH(Proforma!H$3,'Argus Cash Flow Drop'!$B$1:$Z$1,0)),'Argus Cash Flow Drop'!$B$1:$B$98,Proforma!$A11) -> -5159640 | I11: =SUMIFS(INDEX('Argus Cash Flow Drop'!$B$1:$Z$98,0,MATCH(Proforma!I$3,'Argus Cash Flow Drop'!$B$1:$Z$1,0)),'Argus Cash Flow Drop'!$B$1:$B$98,Proforma!$A11) -> -4447950 | J11: =SUMIFS(INDEX('Argus Cash Flow Drop'!$B$1:$Z$98,0,MATCH(Proforma!J$3,'Argus Cash Flow Drop'!$B$1:$Z$1,0)),'Argus Cash Flow Drop'!$B$1:$B$98,Proforma!$A11) -> -7092471 | K11: =SUMIFS(INDEX('Argus Cash Flow Drop'!$B$1:$Z$98,0,MATCH(Proforma!K$3,'Argus Cash Flow Drop'!$B$1:$Z$1,0)),'Argus Cash Flow Drop'!$B$1:$B$98,Proforma!$A11) -> -17970691 | L11: =SUMIFS(INDEX('Argus Cash Flow Drop'!$B$1:$Z$98,0,MATCH(Proforma!L$3,'Argus Cash Flow Drop'!$B$1:$Z$1,0)),'Argus Cash Flow Drop'!$B$1:$B$98,Proforma!$A11) -> -1492850 | M11: =SUMIFS(INDEX('Argus Cash Flow Drop'!$B$1:$Z$98,0,MATCH(Proforma!M$3,'Argus Cash Flow Drop'!$B$1:$Z$1,0)),'Argus Cash Flow Drop'!$B$1:$B$98,Proforma!$A11) -> -1401642 | ... P11: =SUMIFS(INDEX('Argus Cash Flow Drop'!$B$1:$Z$98,0,MATCH(Proforma!P$3,'Argus Cash Flow Drop'!$B$1:$Z$1,0)),'Argus Cash Flow Drop'!$B$1:$B$98,Proforma!$A11) -> -7352362
A12: Free Rent | C12: =F12/$A$2/12 -> -0.17943406 | E12: 0 | F12: =SUMIFS(INDEX('Argus Cash Flow Drop'!$B$1:$Z$98,0,MATCH(Proforma!F$3,'Argus Cash Flow Drop'!$B$1:$Z$1,0)),'Argus Cash Flow Drop'!$B$1:$B$98,Proforma!$A12) -> -6047431 | G12: =SUMIFS(INDEX('Argus Cash Flow Drop'!$B$1:$Z$98,0,MATCH(Proforma!G$3,'Argus Cash Flow Drop'!$B$1:$Z$1,0)),'Argus Cash Flow Drop'!$B$1:$B$98,Proforma!$A12) -> -5519907 | H12: =SUMIFS(INDEX('Argus Cash Flow Drop'!$B$1:$Z$98,0,MATCH(Proforma!H$3,'Argus Cash Flow Drop'!$B$1:$Z$1,0)),'Argus Cash Flow Drop'!$B$1:$B$98,Proforma!$A12) -> -4347120 | I12: =SUMIFS(INDEX('Argus Cash Flow Drop'!$B$1:$Z$98,0,MATCH(Proforma!I$3,'Argus Cash Flow Drop'!$B$1:$Z$1,0)),'Argus Cash Flow Drop'!$B$1:$B$98,Proforma!$A12) -> -2773989 | J12: =SUMIFS(INDEX('Argus Cash Flow Drop'!$B$1:$Z$98,0,MATCH(Proforma!J$3,'Argus Cash Flow Drop'!$B$1:$Z$1,0)),'Argus Cash Flow Drop'!$B$1:$B$98,Proforma!$A12) -> -2060532 | K12: =SUMIFS(INDEX('Argus Cash Flow Drop'!$B$1:$Z$98,0,MATCH(Proforma!K$3,'Argus Cash Flow Drop'!$B$1:$Z$1,0)),'Argus Cash Flow Drop'!$B$1:$B$98,Proforma!$A12) -> -9599230 | L12: =SUMIFS(INDEX('Argus Cash Flow Drop'!$B$1:$Z$98,0,MATCH(Proforma!L$3,'Argus Cash Flow Drop'!$B$1:$Z$1,0)),'Argus Cash Flow Drop'!$B$1:$B$98,Proforma!$A12) -> -859887 | M12: =SUMIFS(INDEX('Argus Cash Flow Drop'!$B$1:$Z$98,0,MATCH(Proforma!M$3,'Argus Cash Flow Drop'!$B$1:$Z$1,0)),'Argus Cash Flow Drop'!$B$1:$B$98,Proforma!$A12) -> -928928 | ... P12: =SUMIFS(INDEX('Argus Cash Flow Drop'!$B$1:$Z$98,0,MATCH(Proforma!P$3,'Argus Cash Flow Drop'!$B$1:$Z$1,0)),'Argus Cash Flow Drop'!$B$1:$B$98,Proforma!$A12) -> -2382661
A13: Scheduled Base Rent | C13: =SUM(C10:C12) -> 4.9484387 | E13: 0 | F13: =SUM(F10:F12) -> 166776261 | G13: =SUM(G10:G12) -> 176478808 | H13: =SUM(H10:H12) -> 191665326 | I13: =SUM(I10:I12) -> 196450250 | J13: =SUM(J10:J12) -> 192713503 | K13: =SUM(K10:K12) -> 162169783 | L13: =SUM(L10:L12) -> 186520150 | M13: =SUM(M10:M12) -> 188862030 | ... P13: =SUM(P10:P12) -> 187989449
A15: Other Income
A16: Total Expense Recoveries | C16: =F16/$A$2/12 -> 0.31643373 | E16: 0 | F16: =SUMIFS(INDEX('Argus Cash Flow Drop'!$B$1:$Z$98,0,MATCH(Proforma!F$3,'Argus Cash Flow Drop'!$B$1:$Z$1,0)),'Argus Cash Flow Drop'!$B$1:$B$98,Proforma!$A16) -> 10664704 | G16: =SUMIFS(INDEX('Argus Cash Flow Drop'!$B$1:$Z$98,0,MATCH(Proforma!G$3,'Argus Cash Flow Drop'!$B$1:$Z$1,0)),'Argus Cash Flow Drop'!$B$1:$B$98,Proforma!$A16) -> 12357653 | H16: =SUMIFS(INDEX('Argus Cash Flow Drop'!$B$1:$Z$98,0,MATCH(Proforma!H$3,'Argus Cash Flow Drop'!$B$1:$Z$1,0)),'Argus Cash Flow Drop'!$B$1:$B$98,Proforma!$A16) -> 13921960 | I16: =SUMIFS(INDEX('Argus Cash Flow Drop'!$B$1:$Z$98,0,MATCH(Proforma!I$3,'Argus Cash Flow Drop'!$B$1:$Z$1,0)),'Argus Cash Flow Drop'!$B$1:$B$98,Proforma!$A16) -> 14912340 | J16: =SUMIFS(INDEX('Argus Cash Flow Drop'!$B$1:$Z$98,0,MATCH(Proforma!J$3,'Argus Cash Flow Drop'!$B$1:$Z$1,0)),'Argus Cash Flow Drop'!$B$1:$B$98,Proforma!$A16) -> 15685452 | K16: =SUMIFS(INDEX('Argus Cash Flow Drop'!$B$1:$Z$98,0,MATCH(Proforma!K$3,'Argus Cash Flow Drop'!$B$1:$Z$1,0)),'Argus Cash Flow Drop'!$B$1:$B$98,Proforma!$A16) -> 11651807 | L16: =SUMIFS(INDEX('Argus Cash Flow Drop'!$B$1:$Z$98,0,MATCH(Proforma!L$3,'Argus Cash Flow Drop'!$B$1:$Z$1,0)),'Argus Cash Flow Drop'!$B$1:$B$98,Proforma!$A16) -> 13941425 | M16: =SUMIFS(INDEX('Argus Cash Flow Drop'!$B$1:$Z$98,0,MATCH(Proforma!M$3,'Argus Cash Flow Drop'!$B$1:$Z$1,0)),'Argus Cash Flow Drop'!$B$1:$B$98,Proforma!$A16) -> 15633018 | ... P16: =SUMIFS(INDEX('Argus Cash Flow Drop'!$B$1:$Z$98,0,MATCH(Proforma!P$3,'Argus Cash Flow Drop'!$B$1:$Z$1,0)),'Argus Cash Flow Drop'!$B$1:$B$98,Proforma!$A16) -> 20489924
A17: Total Tenant Revenue | C17: =SUM(C16:C16) -> 0.31643373 | E17: =SUM(E16:E16) -> 0 | F17: =SUM(F16:F16) -> 10664704 | G17: =SUM(G16:G16) -> 12357653 | H17: =SUM(H16:H16) -> 13921960 | I17: =SUM(I16:I16) -> 14912340 | J17: =SUM(J16:J16) -> 15685452 | K17: =SUM(K16:K16) -> 11651807 | L17: =SUM(L16:L16) -> 13941425 | ... P17: =SUM(P16:P16) -> 20489924
A21: Potential Gross Revenue | C21: =F21/$A$2/12 -> 5.2648725 | E21: =E13+E17+E19 -> 0 | F21: =F13+F17 -> 177440965 | G21: =G13+G17 -> 188836461 | H21: =H13+H17 -> 205587286 | I21: =I13+I17 -> 211362590 | J21: =J13+J17 -> 208398955 | K21: =K13+K17 -> 173821590 | L21: =L13+L17 -> 200461575 | M21: =M13+M17 -> 204495048 | ... P21: =P13+P17 -> 208479373
A23: Vacancy Allowance | C23: =F23/$A$2/12 -> -0.042705735 | E23: 0 | F23: =SUMIFS(INDEX('Argus Cash Flow Drop'!$B$1:$Z$98,0,MATCH(Proforma!F$3,'Argus Cash Flow Drop'!$B$1:$Z$1,0)),'Argus Cash Flow Drop'!$B$1:$B$98,Proforma!$A23) -> -1439303 | G23: =SUMIFS(INDEX('Argus Cash Flow Drop'!$B$1:$Z$98,0,MATCH(Proforma!G$3,'Argus Cash Flow Drop'!$B$1:$Z$1,0)),'Argus Cash Flow Drop'!$B$1:$B$98,Proforma!$A23) -> -6042782 | H23: =SUMIFS(INDEX('Argus Cash Flow Drop'!$B$1:$Z$98,0,MATCH(Proforma!H$3,'Argus Cash Flow Drop'!$B$1:$Z$1,0)),'Argus Cash Flow Drop'!$B$1:$B$98,Proforma!$A23) -> -15915053 | I23: =SUMIFS(INDEX('Argus Cash Flow Drop'!$B$1:$Z$98,0,MATCH(Proforma!I$3,'Argus Cash Flow Drop'!$B$1:$Z$1,0)),'Argus Cash Flow Drop'!$B$1:$B$98,Proforma!$A23) -> -17133104 | J23: =SUMIFS(INDEX('Argus Cash Flow Drop'!$B$1:$Z$98,0,MATCH(Proforma!J$3,'Argus Cash Flow Drop'!$B$1:$Z$1,0)),'Argus Cash Flow Drop'!$B$1:$B$98,Proforma!$A23) -> -14523799 | K23: =SUMIFS(INDEX('Argus Cash Flow Drop'!$B$1:$Z$98,0,MATCH(Proforma!K$3,'Argus Cash Flow Drop'!$B$1:$Z$1,0)),'Argus Cash Flow Drop'!$B$1:$B$98,Proforma!$A23) -> -5377765 | L23: =SUMIFS(INDEX('Argus Cash Flow Drop'!$B$1:$Z$98,0,MATCH(Proforma!L$3,'Argus Cash Flow Drop'!$B$1:$Z$1,0)),'Argus Cash Flow Drop'!$B$1:$B$98,Proforma!$A23) -> -18702592 | M23: =SUMIFS(INDEX('Argus Cash Flow Drop'!$B$1:$Z$98,0,MATCH(Proforma!M$3,'Argus Cash Flow Drop'!$B$1:$Z$1,0)),'Argus Cash Flow Drop'!$B$1:$B$98,Proforma!$A23) -> -19188027 | ... P23: =SUMIFS(INDEX('Argus Cash Flow Drop'!$B$1:$Z$98,0,MATCH(Proforma!P$3,'Argus Cash Flow Drop'!$B$1:$Z$1,0)),'Argus Cash Flow Drop'!$B$1:$B$98,Proforma!$A23) -> -14230812
A24: Credit Loss | C24: =F24/$A$2/12 -> -0.052648735 | E24: 0 | F24: =SUMIFS(INDEX('Argus Cash Flow Drop'!$B$1:$Z$98,0,MATCH(Proforma!F$3,'Argus Cash Flow Drop'!$B$1:$Z$1,0)),'Argus Cash Flow Drop'!$B$1:$B$98,Proforma!$A24) -> -1774410 | G24: =SUMIFS(INDEX('Argus Cash Flow Drop'!$B$1:$Z$98,0,MATCH(Proforma!G$3,'Argus Cash Flow Drop'!$B$1:$Z$1,0)),'Argus Cash Flow Drop'!$B$1:$B$98,Proforma!$A24) -> -1888365 | H24: =SUMIFS(INDEX('Argus Cash Flow Drop'!$B$1:$Z$98,0,MATCH(Proforma!H$3,'Argus Cash Flow Drop'!$B$1:$Z$1,0)),'Argus Cash Flow Drop'!$B$1:$B$98,Proforma!$A24) -> -2055873 | I24: =SUMIFS(INDEX('Argus Cash Flow Drop'!$B$1:$Z$98,0,MATCH(Proforma!I$3,'Argus Cash Flow Drop'!$B$1:$Z$1,0)),'Argus Cash Flow Drop'!$B$1:$B$98,Proforma!$A24) -> -2113626 | J24: =SUMIFS(INDEX('Argus Cash Flow Drop'!$B$1:$Z$98,0,MATCH(Proforma!J$3,'Argus Cash Flow Drop'!$B$1:$Z$1,0)),'Argus Cash Flow Drop'!$B$1:$B$98,Proforma!$A24) -> -2083990 | K24: =SUMIFS(INDEX('Argus Cash Flow Drop'!$B$1:$Z$98,0,MATCH(Proforma!K$3,'Argus Cash Flow Drop'!$B$1:$Z$1,0)),'Argus Cash Flow Drop'!$B$1:$B$98,Proforma!$A24) -> -1738216 | L24: =SUMIFS(INDEX('Argus Cash Flow Drop'!$B$1:$Z$98,0,MATCH(Proforma!L$3,'Argus Cash Flow Drop'!$B$1:$Z$1,0)),'Argus Cash Flow Drop'!$B$1:$B$98,Proforma!$A24) -> -2004616 | M24: =SUMIFS(INDEX('Argus Cash Flow Drop'!$B$1:$Z$98,0,MATCH(Proforma!M$3,'Argus Cash Flow Drop'!$B$1:$Z$1,0)),'Argus Cash Flow Drop'!$B$1:$B$98,Proforma!$A24) -> -2044950 | ... P24: =SUMIFS(INDEX('Argus Cash Flow Drop'!$B$1:$Z$98,0,MATCH(Proforma!P$3,'Argus Cash Flow Drop'!$B$1:$Z$1,0)),'Argus Cash Flow Drop'!$B$1:$B$98,Proforma!$A24) -> -2084794
A25: Total Vacancy & Credit Loss | C25: =SUM(C23:C24) -> -0.09535447 | E25: =SUM(E23:E24) -> 0 | F25: =SUM(F23:F24) -> -3213713 | G25: =SUM(G23:G24) -> -7931147 | H25: =SUM(H23:H24) -> -17970926 | I25: =SUM(I23:I24) -> -19246730 | J25: =SUM(J23:J24) -> -16607789 | K25: =SUM(K23:K24) -> -7115981 | L25: =SUM(L23:L24) -> -20707208 | ... P25: =SUM(P23:P24) -> -16315606
A27: Effective Gross Revenue | C27: =C21+C25 -> 5.169518 | E27: =E21+E25 -> 0 | F27: =F21+F25 -> 174227252 | G27: =G21+G25 -> 180905314 | H27: =H21+H25 -> 187616360 | I27: =I21+I25 -> 192115860 | J27: =J21+J25 -> 191791166 | K27: =K21+K25 -> 166705609 | L27: =L21+L25 -> 179754367 | ... P27: =P21+P25 -> 192163767
A29: OPERATING EXPENSES
A30: CAM | C30: =F30/$A$2/12 -> 0.88554216 | E30: 0 | F30: =SUMIFS(INDEX('Argus Cash Flow Drop'!$A$1:$Z$200,0,MATCH(Proforma!F$3,'Argus Cash Flow Drop'!$A$1:$Z$1,0)),'Argus Cash Flow Drop'!$A$1:$A$200,Proforma!$A30) -> 29845254 | G30: =SUMIFS(INDEX('Argus Cash Flow Drop'!$A$1:$Z$200,0,MATCH(Proforma!G$3,'Argus Cash Flow Drop'!$A$1:$Z$1,0)),'Argus Cash Flow Drop'!$A$1:$A$200,Proforma!$A30) -> 30672357 | H30: =SUMIFS(INDEX('Argus Cash Flow Drop'!$A$1:$Z$200,0,MATCH(Proforma!H$3,'Argus Cash Flow Drop'!$A$1:$Z$1,0)),'Argus Cash Flow Drop'!$A$1:$A$200,Proforma!$A30) -> 31668381 | I30: =SUMIFS(INDEX('Argus Cash Flow Drop'!$A$1:$Z$200,0,MATCH(Proforma!I$3,'Argus Cash Flow Drop'!$A$1:$Z$1,0)),'Argus Cash Flow Drop'!$A$1:$A$200,Proforma!$A30) -> 32338329 | J30: =SUMIFS(INDEX('Argus Cash Flow Drop'!$A$1:$Z$200,0,MATCH(Proforma!J$3,'Argus Cash Flow Drop'!$A$1:$Z$1,0)),'Argus Cash Flow Drop'!$A$1:$A$200,Proforma!$A30) -> 32882661 | K30: =SUMIFS(INDEX('Argus Cash Flow Drop'!$A$1:$Z$200,0,MATCH(Proforma!K$3,'Argus Cash Flow Drop'!$A$1:$Z$1,0)),'Argus Cash Flow Drop'!$A$1:$A$200,Proforma!$A30) -> 33136766 | L30: =SUMIFS(INDEX('Argus Cash Flow Drop'!$A$1:$Z$200,0,MATCH(Proforma!L$3,'Argus Cash Flow Drop'!$A$1:$Z$1,0)),'Argus Cash Flow Drop'!$A$1:$A$200,Proforma!$A30) -> 34441857 | M30: =SUMIFS(INDEX('Argus Cash Flow Drop'!$A$1:$Z$200,0,MATCH(Proforma!M$3,'Argus Cash Flow Drop'!$A$1:$Z$1,0)),'Argus Cash Flow Drop'!$A$1:$A$200,Proforma!$A30) -> 35138544 | ... P30: =SUMIFS(INDEX('Argus Cash Flow Drop'!$A$1:$Z$200,0,MATCH(Proforma!P$3,'Argus Cash Flow Drop'!$A$1:$Z$1,0)),'Argus Cash Flow Drop'!$A$1:$A$200,Proforma!$A30) -> 37043139
A31: REAL ESTATE TAXES | C31: =F31/$A$2/12 -> 1.2764517 | E31: 0 | F31: =SUMIFS(INDEX('Argus Cash Flow Drop'!$A$1:$Z$200,0,MATCH(Proforma!F$3,'Argus Cash Flow Drop'!$A$1:$Z$1,0)),'Argus Cash Flow Drop'!$A$1:$A$200,Proforma!$A31) -> 43020000 | G31: =SUMIFS(INDEX('Argus Cash Flow Drop'!$A$1:$Z$200,0,MATCH(Proforma!G$3,'Argus Cash Flow Drop'!$A$1:$Z$1,0)),'Argus Cash Flow Drop'!$A$1:$A$200,Proforma!$A31) -> 43880400 | H31: =SUMIFS(INDEX('Argus Cash Flow Drop'!$A$1:$Z$200,0,MATCH(Proforma!H$3,'Argus Cash Flow Drop'!$A$1:$Z$1,0)),'Argus Cash Flow Drop'!$A$1:$A$200,Proforma!$A31) -> 44758008 | I31: =SUMIFS(INDEX('Argus Cash Flow Drop'!$A$1:$Z$200,0,MATCH(Proforma!I$3,'Argus Cash Flow Drop'!$A$1:$Z$1,0)),'Argus Cash Flow Drop'!$A$1:$A$200,Proforma!$A31) -> 45653168 | J31: =SUMIFS(INDEX('Argus Cash Flow Drop'!$A$1:$Z$200,0,MATCH(Proforma!J$3,'Argus Cash Flow Drop'!$A$1:$Z$1,0)),'Argus Cash Flow Drop'!$A$1:$A$200,Proforma!$A31) -> 46566232 | K31: =SUMIFS(INDEX('Argus Cash Flow Drop'!$A$1:$Z$200,0,MATCH(Proforma!K$3,'Argus Cash Flow Drop'!$A$1:$Z$1,0)),'Argus Cash Flow Drop'!$A$1:$A$200,Proforma!$A31) -> 47497556 | L31: =SUMIFS(INDEX('Argus Cash Flow Drop'!$A$1:$Z$200,0,MATCH(Proforma!L$3,'Argus Cash Flow Drop'!$A$1:$Z$1,0)),'Argus Cash Flow Drop'!$A$1:$A$200,Proforma!$A31) -> 48447507 | M31: =SUMIFS(INDEX('Argus Cash Flow Drop'!$A$1:$Z$200,0,MATCH(Proforma!M$3,'Argus Cash Flow Drop'!$A$1:$Z$1,0)),'Argus Cash Flow Drop'!$A$1:$A$200,Proforma!$A31) -> 49416457 | ... P31: =SUMIFS(INDEX('Argus Cash Flow Drop'!$A$1:$Z$200,0,MATCH(Proforma!P$3,'Argus Cash Flow Drop'!$A$1:$Z$1,0)),'Argus Cash Flow Drop'!$A$1:$A$200,Proforma!$A31) -> 52441140
A32: UTILITES | C32: =F32/$A$2/12 -> 0.16284313 | E32: 0 | F32: =SUMIFS(INDEX('Argus Cash Flow Drop'!$A$1:$Z$200,0,MATCH(Proforma!F$3,'Argus Cash Flow Drop'!$A$1:$Z$1,0)),'Argus Cash Flow Drop'!$A$1:$A$200,Proforma!$A32) -> 5488270 | G32: =SUMIFS(INDEX('Argus Cash Flow Drop'!$A$1:$Z$200,0,MATCH(Proforma!G$3,'Argus Cash Flow Drop'!$A$1:$Z$1,0)),'Argus Cash Flow Drop'!$A$1:$A$200,Proforma!$A32) -> 5806542 | H32: =SUMIFS(INDEX('Argus Cash Flow Drop'!$A$1:$Z$200,0,MATCH(Proforma!H$3,'Argus Cash Flow Drop'!$A$1:$Z$1,0)),'Argus Cash Flow Drop'!$A$1:$A$200,Proforma!$A32) -> 6269198 | I32: =SUMIFS(INDEX('Argus Cash Flow Drop'!$A$1:$Z$200,0,MATCH(Proforma!I$3,'Argus Cash Flow Drop'!$A$1:$Z$1,0)),'Argus Cash Flow Drop'!$A$1:$A$200,Proforma!$A32) -> 6427715 | J32: =SUMIFS(INDEX('Argus Cash Flow Drop'!$A$1:$Z$200,0,MATCH(Proforma!J$3,'Argus Cash Flow Drop'!$A$1:$Z$1,0)),'Argus Cash Flow Drop'!$A$1:$A$200,Proforma!$A32) -> 6463487 | K32: =SUMIFS(INDEX('Argus Cash Flow Drop'!$A$1:$Z$200,0,MATCH(Proforma!K$3,'Argus Cash Flow Drop'!$A$1:$Z$1,0)),'Argus Cash Flow Drop'!$A$1:$A$200,Proforma!$A32) -> 6227235 | L32: =SUMIFS(INDEX('Argus Cash Flow Drop'!$A$1:$Z$200,0,MATCH(Proforma!L$3,'Argus Cash Flow Drop'!$A$1:$Z$1,0)),'Argus Cash Flow Drop'!$A$1:$A$200,Proforma!$A32) -> 6933606 | M32: =SUMIFS(INDEX('Argus Cash Flow Drop'!$A$1:$Z$200,0,MATCH(Proforma!M$3,'Argus Cash Flow Drop'!$A$1:$Z$1,0)),'Argus Cash Flow Drop'!$A$1:$A$200,Proforma!$A32) -> 7079388 | ... P32: =SUMIFS(INDEX('Argus Cash Flow Drop'!$A$1:$Z$200,0,MATCH(Proforma!P$3,'Argus Cash Flow Drop'!$A$1:$Z$1,0)),'Argus Cash Flow Drop'!$A$1:$A$200,Proforma!$A32) -> 7289734
A33: INSURANCE | C33: =F33/$A$2/12 -> 0.10083333 | E33: 0 | F33: =SUMIFS(INDEX('Argus Cash Flow Drop'!$A$1:$Z$200,0,MATCH(Proforma!F$3,'Argus Cash Flow Drop'!$A$1:$Z$1,0)),'Argus Cash Flow Drop'!$A$1:$A$200,Proforma!$A33) -> 3398366 | G33: =SUMIFS(INDEX('Argus Cash Flow Drop'!$A$1:$Z$200,0,MATCH(Proforma!G$3,'Argus Cash Flow Drop'!$A$1:$Z$1,0)),'Argus Cash Flow Drop'!$A$1:$A$200,Proforma!$A33) -> 3466333 | H33: =SUMIFS(INDEX('Argus Cash Flow Drop'!$A$1:$Z$200,0,MATCH(Proforma!H$3,'Argus Cash Flow Drop'!$A$1:$Z$1,0)),'Argus Cash Flow Drop'!$A$1:$A$200,Proforma!$A33) -> 3535660 | I33: =SUMIFS(INDEX('Argus Cash Flow Drop'!$A$1:$Z$200,0,MATCH(Proforma!I$3,'Argus Cash Flow Drop'!$A$1:$Z$1,0)),'Argus Cash Flow Drop'!$A$1:$A$200,Proforma!$A33) -> 3606373 | J33: =SUMIFS(INDEX('Argus Cash Flow Drop'!$A$1:$Z$200,0,MATCH(Proforma!J$3,'Argus Cash Flow Drop'!$A$1:$Z$1,0)),'Argus Cash Flow Drop'!$A$1:$A$200,Proforma!$A33) -> 3678501 | K33: =SUMIFS(INDEX('Argus Cash Flow Drop'!$A$1:$Z$200,0,MATCH(Proforma!K$3,'Argus Cash Flow Drop'!$A$1:$Z$1,0)),'Argus Cash Flow Drop'!$A$1:$A$200,Proforma!$A33) -> 3752071 | L33: =SUMIFS(INDEX('Argus Cash Flow Drop'!$A$1:$Z$200,0,MATCH(Proforma!L$3,'Argus Cash Flow Drop'!$A$1:$Z$1,0)),'Argus Cash Flow Drop'!$A$1:$A$200,Proforma!$A33) -> 3827112 | M33: =SUMIFS(INDEX('Argus Cash Flow Drop'!$A$1:$Z$200,0,MATCH(Proforma!M$3,'Argus Cash Flow Drop'!$A$1:$Z$1,0)),'Argus Cash Flow Drop'!$A$1:$A$200,Proforma!$A33) -> 3903654 | ... P33: =SUMIFS(INDEX('Argus Cash Flow Drop'!$A$1:$Z$200,0,MATCH(Proforma!P$3,'Argus Cash Flow Drop'!$A$1:$Z$1,0)),'Argus Cash Flow Drop'!$A$1:$A$200,Proforma!$A33) -> 4142589
A34: MGMT FEE | C34: =F34/$A$2/12 -> 0.15508555 | E34: 0 | F34: =SUMIFS(INDEX('Argus Cash Flow Drop'!$A$1:$Z$200,0,MATCH(Proforma!F$3,'Argus Cash Flow Drop'!$A$1:$Z$1,0)),'Argus Cash Flow Drop'!$A$1:$A$200,Proforma!$A34) -> 5226818 | G34: =SUMIFS(INDEX('Argus Cash Flow Drop'!$A$1:$Z$200,0,MATCH(Proforma!G$3,'Argus Cash Flow Drop'!$A$1:$Z$1,0)),'Argus Cash Flow Drop'!$A$1:$A$200,Proforma!$A34) -> 5427159 | H34: =SUMIFS(INDEX('Argus Cash Flow Drop'!$A$1:$Z$200,0,MATCH(Proforma!H$3,'Argus Cash Flow Drop'!$A$1:$Z$1,0)),'Argus Cash Flow Drop'!$A$1:$A$200,Proforma!$A34) -> 5628491 | I34: =SUMIFS(INDEX('Argus Cash Flow Drop'!$A$1:$Z$200,0,MATCH(Proforma!I$3,'Argus Cash Flow Drop'!$A$1:$Z$1,0)),'Argus Cash Flow Drop'!$A$1:$A$200,Proforma!$A34) -> 5763476 | J34: =SUMIFS(INDEX('Argus Cash Flow Drop'!$A$1:$Z$200,0,MATCH(Proforma!J$3,'Argus Cash Flow Drop'!$A$1:$Z$1,0)),'Argus Cash Flow Drop'!$A$1:$A$200,Proforma!$A34) -> 5753735 | K34: =SUMIFS(INDEX('Argus Cash Flow Drop'!$A$1:$Z$200,0,MATCH(Proforma!K$3,'Argus Cash Flow Drop'!$A$1:$Z$1,0)),'Argus Cash Flow Drop'!$A$1:$A$200,Proforma!$A34) -> 5001168 | L34: =SUMIFS(INDEX('Argus Cash Flow Drop'!$A$1:$Z$200,0,MATCH(Proforma!L$3,'Argus Cash Flow Drop'!$A$1:$Z$1,0)),'Argus Cash Flow Drop'!$A$1:$A$200,Proforma!$A34) -> 5392631 | M34: =SUMIFS(INDEX('Argus Cash Flow Drop'!$A$1:$Z$200,0,MATCH(Proforma!M$3,'Argus Cash Flow Drop'!$A$1:$Z$1,0)),'Argus Cash Flow Drop'!$A$1:$A$200,Proforma!$A34) -> 5497862 | ... P34: =SUMIFS(INDEX('Argus Cash Flow Drop'!$A$1:$Z$200,0,MATCH(Proforma!P$3,'Argus Cash Flow Drop'!$A$1:$Z$1,0)),'Argus Cash Flow Drop'!$A$1:$A$200,Proforma!$A34) -> 5764913
A35: Total Operating Expenses | C35: =SUM(C30:C34) -> 2.5807558 | E35: =SUM(E30:E34) -> 0 | F35: =SUM(F30:F34) -> 86978708 | G35: =SUM(G30:G34) -> 89252791 | H35: =SUM(H30:H34) -> 91859738 | I35: =SUM(I30:I34) -> 93789061 | J35: =SUM(J30:J34) -> 95344616 | K35: =SUM(K30:K34) -> 95614796 | L35: =SUM(L30:L34) -> 99042713 | ... P35: =SUM(P30:P34) -> 106681515
A37: Net Operating Income | C37: =C27-C35 -> 2.5887622 | E37: =E27-E35 -> 0 | F37: =F27-F35 -> 87248544 | G37: =G27-G35 -> 91652523 | H37: =H27-H35 -> 95756622 | I37: =I27-I35 -> 98326799 | J37: =J27-J35 -> 96446550 | K37: =K27-K35 -> 71090813 | L37: =L27-L35 -> 80711654 | ... P37: =P27-P35 -> 85482252
A39: LEASING AND CAPITAL COSTS
A40: Tenant Improvements | C40: =F40/$A$2/12 -> 1.0370019 | E40: 0 | F40: =SUMIFS(INDEX('Argus Cash Flow Drop'!$B$1:$Z$98,0,MATCH(Proforma!F$3,'Argus Cash Flow Drop'!$B$1:$Z$1,0)),'Argus Cash Flow Drop'!$B$1:$B$98,Proforma!$A40) -> 34949871 | G40: =SUMIFS(INDEX('Argus Cash Flow Drop'!$B$1:$Z$98,0,MATCH(Proforma!G$3,'Argus Cash Flow Drop'!$B$1:$Z$1,0)),'Argus Cash Flow Drop'!$B$1:$B$98,Proforma!$A40) -> 22950092 | H40: =SUMIFS(INDEX('Argus Cash Flow Drop'!$B$1:$Z$98,0,MATCH(Proforma!H$3,'Argus Cash Flow Drop'!$B$1:$Z$1,0)),'Argus Cash Flow Drop'!$B$1:$B$98,Proforma!$A40) -> 13696597 | I40: =SUMIFS(INDEX('Argus Cash Flow Drop'!$B$1:$Z$98,0,MATCH(Proforma!I$3,'Argus Cash Flow Drop'!$B$1:$Z$1,0)),'Argus Cash Flow Drop'!$B$1:$B$98,Proforma!$A40) -> 10184088 | J40: =SUMIFS(INDEX('Argus Cash Flow Drop'!$B$1:$Z$98,0,MATCH(Proforma!J$3,'Argus Cash Flow Drop'!$B$1:$Z$1,0)),'Argus Cash Flow Drop'!$B$1:$B$98,Proforma!$A40) -> 8652727 | K40: =SUMIFS(INDEX('Argus Cash Flow Drop'!$B$1:$Z$98,0,MATCH(Proforma!K$3,'Argus Cash Flow Drop'!$B$1:$Z$1,0)),'Argus Cash Flow Drop'!$B$1:$B$98,Proforma!$A40) -> 53012645 | L40: =SUMIFS(INDEX('Argus Cash Flow Drop'!$B$1:$Z$98,0,MATCH(Proforma!L$3,'Argus Cash Flow Drop'!$B$1:$Z$1,0)),'Argus Cash Flow Drop'!$B$1:$B$98,Proforma!$A40) -> 3063045 | M40: =SUMIFS(INDEX('Argus Cash Flow Drop'!$B$1:$Z$98,0,MATCH(Proforma!M$3,'Argus Cash Flow Drop'!$B$1:$Z$1,0)),'Argus Cash Flow Drop'!$B$1:$B$98,Proforma!$A40) -> 3405628 | ... P40: =SUMIFS(INDEX('Argus Cash Flow Drop'!$B$1:$Z$98,0,MATCH(Proforma!P$3,'Argus Cash Flow Drop'!$B$1:$Z$1,0)),'Argus Cash Flow Drop'!$B$1:$B$98,Proforma!$A40) -> 11960829
